Workbook

Sheet Shot List
A1: Photo | B1: Env | C1: Slot | D1: # | E1: Filename | F1: Group | G1: Triplet | H1: LEFT hand | I1: RIGHT hand | J1: Rotation | K1: Expected labels | L1: N | M1: Shot? | N1: Mask? | O1: QA? | P1: Notes
A2: P01 | B2: E01 | C2: S1 | D2: 1 | E2: E01_P01.jpg | F2: fold0 | G2: diagonal | H2: openhand | I2: openhand | J2: 0 | K2: 1 1 | L2: 2
A3: P02 | B3: E01 | C3: S1 | D3: 2 | E3: E01_P02.jpg | F3: fold0 | G3: diagonal | H3: closedhand | I3: closedhand | J3: 30 | K3: 2 2 | L3: 2
A4: P03 | B4: E01 | C4: S1 | D4: 3 | E4: E01_P03.jpg | F4: fold0 | G4: diagonal | H4: thumbout | I4: thumbout | J4: 60 | K4: 0 0 | L4: 2
A5: P04 | B5: E02 | C5: S2 | D5: 1 | E5: E02_P04.jpg | F5: fold0 | G5: cycleA | H5: openhand | I5: closedhand | J5: 0 | K5: 1 2 | L5: 2
A6: P05 | B6: E02 | C6: S2 | D6: 2 | E6: E02_P05.jpg | F6: fold0 | G6: cycleA | H6: closedhand | I6: thumbout | J6: 30 | K6: 2 0 | L6: 2
A7: P06 | B7: E02 | C7: S2 | D7: 3 | E7: E02_P06.jpg | F7: fold0 | G7: cycleA | H7: thumbout | I7: openhand | J7: 60 | K7: 0 1 | L7: 2
A8: P07 | B8: E02 | C8: S2 | D8: 4 | E8: E02_P07.jpg | F8: fold0 | G8: cycleB | H8: openhand | I8: thumbout | J8: 60 | K8: 1 0 | L8: 2
A9: P08 | B9: E02 | C9: S2 | D9: 5 | E9: E02_P08.jpg | F9: fold0 | G9: cycleB | H9: thumbout | I9: closedhand | J9: 30 | K9: 0 2 | L9: 2
A10: P09 | B10: E02 | C10: S2 | D10: 6 | E10: E02_P09.jpg | F10: fold0 | G10: cycleB | H10: closedhand | I10: openhand | J10: 0 | K10: 2 1 | L10: 2
A11: P10 | B11: E03 | C11: S3 | D11: 1 | E11: E03_P10.jpg | F11: fold0 | G11: cycleA | H11: openhand | I11: closedhand | J11: 0 | K11: 1 2 | L11: 2
A12: P11 | B12: E03 | C12: S3 | D12: 2 | E12: E03_P11.jpg | F12: fold0 | G12: cycleA | H12: closedhand | I12: thumbout | J12: 30 | K12: 2 0 | L12: 2
A13: P12 | B13: E03 | C13: S3 | D13: 3 | E13: E03_P12.jpg | F13: fold0 | G13: cycleA | H13: thumbout | I13: openhand | J13: 60 | K13: 0 1 | L13: 2
... A61: P60 | B61: E12 | C61: S3 | D61: 6 | E61: E12_P60.jpg | F61: test | G61: cycleB | H61: closedhand | I61: openhand | J61: 0 | K61: 2 1 | L61: 2

Sheet Balance Check
A1: LIVE CHECK — every green cell must stay green. Edit the Shot List and these recompute.
A3: Annotations per class (target 10 per group, 40 total)
A4: Group | B4: thumbout | C4: openhand | D4: closedhand | E4: Photos | F4: Annotations
A5: fold0 | B5: =COUNTIFS('Shot List'!$F$2:$F$61,$A5,'Shot List'!$H$2:$H$61,B$4)+COUNTIFS('Shot List'!$F$2:$F$61,$A5,'Shot List'!$I$2:$I$61,B$4) | C5: =COUNTIFS('Shot List'!$F$2:$F$61,$A5,'Shot List'!$H$2:$H$61,C$4)+COUNTIFS('Shot List'!$F$2:$F$61,$A5,'Shot List'!$I$2:$I$61,C$4) | D5: =COUNTIFS('Shot List'!$F$2:$F$61,$A5,'Shot List'!$H$2:$H$61,D$4)+COUNTIFS('Shot List'!$F$2:$F$61,$A5,'Shot List'!$I$2:$I$61,D$4) | E5: =COUNTIF('Shot List'!$F$2:$F$61,$A5) | F5: =SUM(B5:D5)
A6: fold1 | B6: =COUNTIFS('Shot List'!$F$2:$F$61,$A6,'Shot List'!$H$2:$H$61,B$4)+COUNTIFS('Shot List'!$F$2:$F$61,$A6,'Shot List'!$I$2:$I$61,B$4) | C6: =COUNTIFS('Shot List'!$F$2:$F$61,$A6,'Shot List'!$H$2:$H$61,C$4)+COUNTIFS('Shot List'!$F$2:$F$61,$A6,'Shot List'!$I$2:$I$61,C$4) | D6: =COUNTIFS('Shot List'!$F$2:$F$61,$A6,'Shot List'!$H$2:$H$61,D$4)+COUNTIFS('Shot List'!$F$2:$F$61,$A6,'Shot List'!$I$2:$I$61,D$4) | E6: =COUNTIF('Shot List'!$F$2:$F$61,$A6) | F6: =SUM(B6:D6)
A7: fold2 | B7: =COUNTIFS('Shot List'!$F$2:$F$61,$A7,'Shot List'!$H$2:$H$61,B$4)+COUNTIFS('Shot List'!$F$2:$F$61,$A7,'Shot List'!$I$2:$I$61,B$4) | C7: =COUNTIFS('Shot List'!$F$2:$F$61,$A7,'Shot List'!$H$2:$H$61,C$4)+COUNTIFS('Shot List'!$F$2:$F$61,$A7,'Shot List'!$I$2:$I$61,C$4) | D7: =COUNTIFS('Shot List'!$F$2:$F$61,$A7,'Shot List'!$H$2:$H$61,D$4)+COUNTIFS('Shot List'!$F$2:$F$61,$A7,'Shot List'!$I$2:$I$61,D$4) | E7: =COUNTIF('Shot List'!$F$2:$F$61,$A7) | F7: =SUM(B7:D7)
A8: test | B8: =COUNTIFS('Shot List'!$F$2:$F$61,$A8,'Shot List'!$H$2:$H$61,B$4)+COUNTIFS('Shot List'!$F$2:$F$61,$A8,'Shot List'!$I$2:$I$61,B$4) | C8: =COUNTIFS('Shot List'!$F$2:$F$61,$A8,'Shot List'!$H$2:$H$61,C$4)+COUNTIFS('Shot List'!$F$2:$F$61,$A8,'Shot List'!$I$2:$I$61,C$4) | D8: =COUNTIFS('Shot List'!$F$2:$F$61,$A8,'Shot List'!$H$2:$H$61,D$4)+COUNTIFS('Shot List'!$F$2:$F$61,$A8,'Shot List'!$I$2:$I$61,D$4) | E8: =COUNTIF('Shot List'!$F$2:$F$61,$A8) | F8: =SUM(B8:D8)
A9: TOTAL | B9: =SUM(B5:B8) | C9: =SUM(C5:C8) | D9: =SUM(D5:D8) | E9: =SUM(E5:E8) | F9: =SUM(F5:F8)
A12: Per hand side (target 5 per class per side, per group)
A13: Group | B13: thumbout L | C13: openhand L | D13: closedhand L | E13: thumbout R | F13: openhand R | G13: closedhand R
A14: fold0 | B14: =COUNTIFS('Shot List'!$F$2:$F$61,$A14,'Shot List'!$H$2:$H$61,"thumbout") | C14: =COUNTIFS('Shot List'!$F$2:$F$61,$A14,'Shot List'!$H$2:$H$61,"openhand") | D14: =COUNTIFS('Shot List'!$F$2:$F$61,$A14,'Shot List'!$H$2:$H$61,"closedhand") | E14: =COUNTIFS('Shot List'!$F$2:$F$61,$A14,'Shot List'!$I$2:$I$61,"thumbout") | F14: =COUNTIFS('Shot List'!$F$2:$F$61,$A14,'Shot List'!$I$2:$I$61,"openhand") | G14: =COUNTIFS('Shot List'!$F$2:$F$61,$A14,'Shot List'!$I$2:$I$61,"closedhand")
A15: fold1 | B15: =COUNTIFS('Shot List'!$F$2:$F$61,$A15,'Shot List'!$H$2:$H$61,"thumbout") | C15: =COUNTIFS('Shot List'!$F$2:$F$61,$A15,'Shot List'!$H$2:$H$61,"openhand") | D15: =COUNTIFS('Shot List'!$F$2:$F$61,$A15,'Shot List'!$H$2:$H$61,"closedhand") | E15: =COUNTIFS('Shot List'!$F$2:$F$61,$A15,'Shot List'!$I$2:$I$61,"thumbout") | F15: =COUNTIFS('Shot List'!$F$2:$F$61,$A15,'Shot List'!$I$2:$I$61,"openhand") | G15: =COUNTIFS('Shot List'!$F$2:$F$61,$A15,'Shot List'!$I$2:$I$61,"closedhand")
A16: fold2 | B16: =COUNTIFS('Shot List'!$F$2:$F$61,$A16,'Shot List'!$H$2:$H$61,"thumbout") | C16: =COUNTIFS('Shot List'!$F$2:$F$61,$A16,'Shot List'!$H$2:$H$61,"openhand") | D16: =COUNTIFS('Shot List'!$F$2:$F$61,$A16,'Shot List'!$H$2:$H$61,"closedhand") | E16: =COUNTIFS('Shot List'!$F$2:$F$61,$A16,'Shot List'!$I$2:$I$61,"thumbout") | F16: =COUNTIFS('Shot List'!$F$2:$F$61,$A16,'Shot List'!$I$2:$I$61,"openhand") | G16: =COUNTIFS('Shot List'!$F$2:$F$61,$A16,'Shot List'!$I$2:$I$61,"closedhand")
A17: test | B17: =COUNTIFS('Shot List'!$F$2:$F$61,$A17,'Shot List'!$H$2:$H$61,"thumbout") | C17: =COUNTIFS('Shot List'!$F$2:$F$61,$A17,'Shot List'!$H$2:$H$61,"openhand") | D17: =COUNTIFS('Shot List'!$F$2:$F$61,$A17,'Shot List'!$H$2:$H$61,"closedhand") | E17: =COUNTIFS('Shot List'!$F$2:$F$61,$A17,'Shot List'!$I$2:$I$61,"thumbout") | F17: =COUNTIFS('Shot List'!$F$2:$F$61,$A17,'Shot List'!$I$2:$I$61,"openhand") | G17: =COUNTIFS('Shot List'!$F$2:$F$61,$A17,'Shot List'!$I$2:$I$61,"closedhand")
A19: Rotation balance (target 20 photos at each)
A20: Rotation | B20: Photos
A21: 0 | B21: =COUNTIF('Shot List'!$J$2:$J$61,$A21)
A22: 30 | B22: =COUNTIF('Shot List'!$J$2:$J$61,$A22)
A23: 60 | B23: =COUNTIF('Shot List'!$J$2:$J$61,$A23)
A25: Progress
A26: Photos shot | B26: =COUNTA('Shot List'!$M$2:$M$61) | C26: of 60
A27: Masks done | B27: =COUNTA('Shot List'!$N$2:$N$61) | C27: of 60
A28: QA passed | B28: =COUNTA('Shot List'!$O$2:$O$61) | C28: of 60

Sheet Setup Cards
A1: E01 — home office desk (fold0, slot S1)
A2: Background | B2: plain wall behind the desk
A3: Lighting | B3: diffuse window daylight (overcast or shaded), no lamp on (~800 lux, daylight)
A4: Camera | B4: 55 cm from hands, screen tilt 0°
A5: Wear | B5: short sleeves, forearms bare
A6: Session | B6: A-day, daytime
A8: Photo | B8: File | C8: LEFT hand | D8: RIGHT hand | E8: Rotation | F8: Shot?
A9: P01 | B9: E01_P01.jpg | C9: openhand | D9: openhand | E9: 0°
A10: P02 | B10: E01_P02.jpg | C10: closedhand | D10: closedhand | E10: 30°
A11: P03 | B11: E01_P03.jpg | C11: thumbout | D11: thumbout | E11: 60°
A14: E02 — kitchen (fold0, slot S2)
A15: Background | B15: tiled splashback or cupboard fronts
A16: Lighting | B16: ceiling light only, curtains or blinds shut (~300 lux, artificial)
A17: Camera | B17: 65 cm from hands, screen tilt -15°
A18: Wear | B18: long sleeves, striped or patterned + wristwatch on the image-left hand
A19: Session | B19: A-night, evening
A21: Photo | B21: File | C21: LEFT hand | D21: RIGHT hand | E21: Rotation | F21: Shot?
A22: P04 | B22: E02_P04.jpg | C22: openhand | D22: closedhand | E22: 0°
A23: P05 | B23: E02_P05.jpg | C23: closedhand | D23: thumbout | E23: 30°
A24: P06 | B24: E02_P06.jpg | C24: thumbout | D24: openhand | E24: 60°
A25: P07 | B25: E02_P07.jpg | C25: openhand | D25: thumbout | E25: 60°
A26: P08 | B26: E02_P08.jpg | C26: thumbout | D26: closedhand | E26: 30°
A27: P09 | B27: E02_P09.jpg | C27: closedhand | D27: openhand | E27: 0°
A30: E03 — bedroom (fold0, slot S3)
A31: Background | B31: duvet and folded fabric
A32: Lighting | B32: one dim lamp only, no ceiling light (~60 lux, artificial)
A33: Camera | B33: 75 cm from hands, screen tilt 20°
A34: Wear | B34: long dark sleeves or hoodie cuffs + bracelet on the image-right hand
A35: Session | B35: A-night, evening
A37: Photo | B37: File | C37: LEFT hand | D37: RIGHT hand | E37: Rotation | F37: Shot?
A38: P10 | B38: E03_P10.jpg | C38: openhand | D38: closedhand | E38: 0°
A39: P11 | B39: E03_P11.jpg | C39: closedhand | D39: thumbout | E39: 30°
A40: P12 | B40: E03_P12.jpg | C40: thumbout | D40: openhand | E40: 60°
A41: P13 | B41: E03_P13.jpg | C41: openhand | D41: thumbout | E41: 60°
A42: P14 | B42: E03_P14.jpg | C42: thumbout | D42: closedhand | E42: 30°
A43: P15 | B43: E03_P15.jpg | C43: closedhand | D43: openhand | E43: 0°
A46: E04 — living room (fold1, slot S1)
A47: Background | B47: plain painted wall
A48: Lighting | B48: diffuse window daylight (overcast or shaded), no lamp on (~800 lux, daylight)
A49: Camera | B49: 55 cm from hands, screen tilt 0°
...

Sheet Environments
A1: Env | B1: Group | C1: Slot | D1: Room (CONFIRM) | E1: Background | F1: Light | G1: Light source | H1: Lux | I1: Distance cm | J1: Tilt deg | K1: Sleeve | L1: Accessory | M1: Side | N1: Difficulty | O1: Photos | P1: Photo IDs | Q1: Session | R1: Time | S1: Confirmed? | T1: Notes
A2: E01 | B2: fold0 | C2: S1 | D2: home office desk | E2: plain wall behind the desk | F2: daylight | G2: diffuse window daylight (overcast or shaded), no lamp on | H2: 800 | I2: 55 | J2: 0 | K2: short sleeves, forearms bare | L2: none | N2: easy | O2: 3 | P2: P01-P03 | Q2: A-day | R2: daytime
A3: E02 | B3: fold0 | C3: S2 | D3: kitchen | E3: tiled splashback or cupboard fronts | F3: artificial | G3: ceiling light only, curtains or blinds shut | H3: 300 | I3: 65 | J3: -15 | K3: long sleeves, striped or patterned | L3: wristwatch | M3: image-left | N3: medium | O3: 6 | P3: P04-P09 | Q3: A-night | R3: evening
A4: E03 | B4: fold0 | C4: S3 | D4: bedroom | E4: duvet and folded fabric | F4: artificial | G4: one dim lamp only, no ceiling light | H4: 60 | I4: 75 | J4: 20 | K4: long dark sleeves or hoodie cuffs | L4: bracelet | M4: image-right | N4: hard | O4: 6 | P4: P10-P15 | Q4: A-night | R4: evening
A5: E04 | B5: fold1 | C5: S1 | D5: living room | E5: plain painted wall | F5: daylight | G5: diffuse window daylight (overcast or shaded), no lamp on | H5: 800 | I5: 55 | J5: 0 | K5: short sleeves, forearms bare | L5: none | N5: easy | O5: 3 | P5: P16-P18 | Q5: B-day | R5: daytime
A6: E05 | B6: fold1 | C6: S2 | D6: hallway | E6: closed internal door, flat panel | F6: artificial | G6: ceiling light only, curtains or blinds shut | H6: 300 | I6: 65 | J6: -15 | K6: long sleeves, striped or patterned | L6: wristwatch | M6: image-left | N6: medium | O6: 6 | P6: P19-P24 | Q6: B-night | R6: evening
A7: E06 | B7: fold1 | C7: S3 | D7: dining room | E7: wooden table and chair backs | F7: artificial | G7: one dim lamp only, no ceiling light | H7: 60 | I7: 75 | J7: 20 | K7: long dark sleeves or hoodie cuffs | L7: bracelet | M7: image-right | N7: hard | O7: 6 | P7: P25-P30 | Q7: B-night | R7: evening
A8: E07 | B8: fold2 | C8: S1 | D8: spare room | E8: bookshelf with book spines (busy) | F8: daylight | G8: diffuse window daylight (overcast or shaded), no lamp on | H8: 800 | I8: 55 | J8: 0 | K8: short sleeves, forearms bare | L8: none | N8: easy | O8: 3 | P8: P31-P33 | Q8: C-day | R8: daytime
A9: E08 | B9: fold2 | C9: S2 | D9: landing or stairs | E9: stair wall and banister | F9: artificial | G9: ceiling light only, curtains or blinds shut | H9: 300 | I9: 65 | J9: -15 | K9: long sleeves, striped or patterned | L9: wristwatch | M9: image-left | N9: medium | O9: 6 | P9: P34-P39 | Q9: C-night | R9: evening
A10: E09 | B10: fold2 | C10: S3 | D10: entryway | E10: coat rack with hanging coats | F10: artificial | G10: one dim lamp only, no ceiling light | H10: 60 | I10: 75 | J10: 20 | K10: long dark sleeves or hoodie cuffs | L10: bracelet | M10: image-right | N10: hard | O10: 6 | P10: P40-P45 | Q10: C-night | R10: evening
A11: E10 | B11: test | C11: S1 | D11: balcony or doorway | E11: outdoor greenery, depth behind hands | F11: daylight | G11: diffuse window daylight (overcast or shaded), no lamp on | H11: 800 | I11: 55 | J11: 0 | K11: short sleeves, forearms bare | L11: none | N11: easy | O11: 3 | P11: P46-P48 | Q11: X-day | R11: daytime | T11: TEST - room must not appear in training
A12: E11 | B12: test | C12: S2 | D12: bathroom | E12: white wall tiles, no mirror in frame | F12: artificial | G12: ceiling light only, curtains or blinds shut | H12: 300 | I12: 65 | J12: -15 | K12: long sleeves, striped or patterned | L12: wristwatch | M12: image-left | N12: medium | O12: 6 | P12: P49-P54 | Q12: X-night | R12: evening | T12: TEST - room must not appear in training
A13: E12 | B13: test | C13: S3 | D13: garage or utility | E13: unfinished wall and shelving | F13: artificial | G13: one dim lamp only, no ceiling light | H13: 60 | I13: 75 | J13: 20 | K13: long dark sleeves or hoodie cuffs | L13: bracelet | M13: image-right | N13: hard | O13: 6 | P13: P55-P60 | Q13: X-night | R13: evening | T13: TEST - room must not appear in training

Sheet Protocol
B1: THE RULES THAT MATTER MOST
A2: • | B2: Lock the camera's exposure, white balance and focus BEFORE the first photo of an environment, and do not let them change between the photos of that environment. If the camera re-meters between an open hand and a fist, brightness becomes a clue to the gesture and the whole environment is wasted. This cannot be fixed afterwards.
A3: • | B3: Keep the 18% grey card taped in the same corner of the frame for all 60 photos. It is how we prove the exposure stayed locked.
A4: • | B4: Do not touch the laptop between the photos of one environment. Use the delayed trigger so both hands are free.
A5: • | B5: Both hands must be fully inside the frame, not overlapping each other, with a gap of about one hand-width between them.
B7: SETTING UP AN ENVIRONMENT
A8: • | B8: Position the laptop at the distance and screen tilt on the setup card.
A9: • | B9: Set the lighting exactly as the card says. Nothing else on.
A10: • | B10: Put on the sleeves and accessory the card specifies.
A11: • | B11: Tape the grey card into the top-left of the frame.
A12: • | B12: Lock exposure / white balance / focus.
A13: • | B13: Shoot the photos in the order on the card. Do not reorder them.
B15: THE GESTURES
A16: • | B16: open hand — all five fingers extended and spread, palm to the camera.
A17: • | B17: closed hand — a fist, fingers curled in, thumb resting against the index finger.
A18: • | B18: thumb out — fingers curled into a fist, thumb extended clearly away from the fist.
A19: • | B19: Rotation is in the plane of the screen: the palm stays facing the camera and the whole hand rotates. 0° = fingers point straight up. 30° and 60° = tilted by that much. Rotate both hands by the same amount.
B21: WHAT MAKES A PHOTO INVALID — reshoot it
A22: • | B22: Either hand is cut off by the frame edge.
A23: • | B23: The hands overlap or touch each other.
A24: • | B24: Motion blur — hold still through the shutter delay.
A25: • | B25: The gesture is ambiguous (a half-closed hand is neither open nor closed).
A26: • | B26: The grey card is missing, obscured, or blown out.
A27: • | B27: The exposure visibly changed from the previous photo in the same environment.
B29: ORDER OF WORK
A30: • | B30: Confirm every room on the Environments sheet exists and is free. Mark Confirmed?.
A31: • | B31: Measure the webcam's field of view with a ruler at 55 cm and 75 cm before locking the distances. If the frame is narrower than expected, add the same amount to all three distances rather than changing them individually.
A32: • | B32: Shoot E01 first as a pilot, all the way through masks and QA, before shooting anything else. It is cheaper to find a problem in 3 photos than in 60.
A33: • | B33: Never shoot a test environment (E10, E11, E12) in the same session as a training one.
A34: • | B34: Shoot the dark, hard environments first in each session, while you are fresh.
B36: WHY THE DESIGN LOOKS LIKE THIS
A37: • | B37: Every environment contains each gesture exactly the same number of times, on each hand. So the background, the lighting and the sleeve carry no information about which gesture is being made, and the model cannot take a shortcut.
A38: • | B38: All twelve places are split so that a place is only ever in one fold. The three test places appear nowhere in training, which is what lets us claim the model works in a room it has never seen.
A39: • | B39: The four groups match on distance, tilt, lighting, sleeve and difficulty, so when the three fold scores differ, the difference is caused by the places themselves and nothing else.
